outputs/llm_tags.csv
sentence_id,damsl_tags,beads_tags,n_damsl_tags,n_beads_tags
1001_t0001_s001,GR,,1,0
1001_t0001_s002,GR,,1,0
1001_t0001_s003,S,,1,0
1001_t0001_s004,S,,1,0
1001_t0001_s005,S,,1,0
1001_t0001_s006,S,,1,0
1001_t0002_s001,S,,1,0
1001_t0002_s002,S,,1,0
1001_t0002_s003,S,,1,0
1001_t0002_s004,S; TG,,2,0
1001_t0002_s005,S-Inform,,1,0
1001_t0002_s006,Q-W; OQ,,2,0
1001_t0003_s001,S; IAFA,IP,2,1
1001_t0003_s002,S,IP,1,1
1001_t0003_s003,S,IP; SE,1,2
1001_t0003_s004,S,UF; IP,1,2
1001_t0003_s005,S,IP,1,1
1001_t0003_s006,S,IP,1,1
1001_t0003_s007,S,UF,1,1
1001_t0003_s008,S,UF,1,1
1001_t0003_s009,S,,1,0
1001_t0003_s010,S,UF,1,1
1001_t0003_s011,S; HS,,2,0
1001_t0003_s012,S,,1,0
1001_t0003_s013,S,,1,0
1001_t0003_s014,S,UF,1,1
1001_t0003_s015,S,,1,0
1001_t0003_s016,S,UF,1,1
1001_t0003_s017,S,AE; UF,1,2
1001_t0003_s018,S,IT,1,1
1001_t0003_s019,S; IAFA,AE; UF,2,2
1001_t0004_s001,S,,1,0
1001_t0005_s001,AGR,,1,0
1001_t0005_s002,S; AGR,,2,0
1001_t0005_s003,S,IP,1,1
1001_t0005_s004,S,UF,1,1
1001_t0005_s005,S,AF; ATTR,1,2
1001_t0005_s006,S,AE; ATTR,1,2
1001_t0005_s007,S,IT,1,1
1001_t0005_s008,S; HS,AE,2,1
1001_t0005_s009,S,IT,1,1
1001_t0005_s010,S,IP; ATTR,1,2
1001_t0005_s011,S,IP,1,1
1001_t0005_s012,S; HS,IP,2,1
1001_t0006_s001,MS,,1,0
1001_t0006_s002,S,,1,0
1001_t0006_s003,YNQ,REB; CB,1,2
1001_t0007_s001,S; IAFA; APO,,3,0
1001_t0007_s002,S,,1,0
1001_t0007_s003,S; AGR,,2,0
1001_t0007_s004,S; EXPL,AE; CB,2,2
1001_t0007_s005,S; S-Inform; IAFA-OF,IT,3,1
1001_t0007_s006,S,,1,0
1001_t0007_s007,S; S-Inform,,2,0
1001_t0007_s008,S; S-Inform,SE,2,1
1001_t0007_s009,S,,1,0
1001_t0007_s010,S,UF; IP,1,2
1001_t0008_s001,IAFA-OF; TG,,2,0
1001_t0009_s001,AGR,,1,0
1001_t0009_s002,S; AGR,,2,0
1001_t0009_s003,S,IP,1,1
1001_t0009_s004,S,,1,0
1001_t0009_s005,S,PB; ATTR,1,2
1001_t0009_s006,S,AF; ATTR,1,2
1001_t0009_s007,S,IT,1,1
1001_t0009_s008,S; HS,AE,2,1
1001_t0009_s009,S,IT,1,1
1001_t0009_s010,S,AF; IP; ATTR,1,3
1001_t0009_s011,S,IP,1,1
1001_t0009_s012,S,IT; IP,1,2
1001_t0010_s001,S,,1,0
1001_t0010_s002,S-Inform,,1,0
1001_t0010_s003,YNQ,REB; CB,1,2
1001_t0011_s001,S; IAFA; IAFA-OF,IT; IP,3,2
1001_t0011_s002,S,,1,0
1001_t0011_s003,S; AGR,,2,0
1001_t0011_s004,S; EXPL,AE; REB; CB,2,3
1001_t0011_s005,S; S-Inform,IT,2,1
1001_t0011_s006,S,,1,0
1001_t0011_s007,S; S-Inform,,2,0
1001_t0011_s008,S-Inform,SE,1,1
1001_t0011_s009,S-Inform; INT,AP; IT,2,2
1001_t0011_s010,S,IT,1,1
1001_t0011_s011,S,UF; IT,1,2
1001_t0011_s012,S,AE; UF,1,2
1001_t0011_s013,S; TT,,2,0
1001_t0011_s014,Q-W,REB,1,1
1001_t0011_s015,S; CH,ATTR; REB,2,2
1001_t0012_s001,TG,,1,0
1001_t0012_s002,TG,,1,0
1001_t0013_s001,S,,1,0
1001_t0013_s002,S,IT,1,1
1001_t0013_s003,S,IT,1,1
1001_t0013_s004,S,,1,0
1001_t0013_s005,S; HS,,2,0
1001_t0013_s006,S,,1,0
1001_t0013_s007,S; HS,IT,2,1
1001_t0013_s008,S,REB,1,1
1001_t0013_s009,S; S-Inform,IT; SE,2,2
1001_t0013_s010,S; IAFA,DF; IP,2,2
1001_t0013_s011,S,,1,0
1001_t0013_s012,S; HS,IT,2,1
1001_t0013_s013,S; HS,IT,2,1
1001_t0013_s014,S,,1,0
1001_t0013_s015,IAFA,REB,1,1
1001_t0014_s001,S,,1,0
1001_t0014_s002,S,,1,0
1001_t0015_s001,S; HS,,2,0
1001_t0015_s002,S,,1,0
1001_t0015_s003,Q-W; OQ,,2,0
1001_t0016_s001,ANS,,1,0
1001_t0016_s002,S; IAFA; TT,IT,3,1
1001_t0016_s003,S,IT; IP,1,2
1001_t0016_s004,S,,1,0
1001_t0016_s005,S; REJ,IP; REB,2,2
1001_t0016_s006,S,IT,1,1
1001_t0016_s007,S,UF,1,1
1001_t0016_s008,S,,1,0
1001_t0016_s009,S,,1,0
1001_t0016_s010,S; S-Inform,UF,2,1
1001_t0016_s011,S,AE,1,1
1001_t0016_s012,S,IP,1,1
1001_t0016_s013,S; S-Inform,ATTR; SE,2,2
1001_t0016_s014,S,UF,1,1
1001_t0016_s015,S,,1,0
1001_t0016_s016,S; CH,ATTR; REB,2,2
1001_t0016_s017,S; S-Inform; CH,PER; ATTR; REB; SE,3,4
1001_t0016_s018,S,REB,1,1
1001_t0016_s019,S,PER; AEX,1,2
1001_t0017_s001,TT; T-REQ,,2,0
1001_t0017_s002,TT,,1,0
1001_t0018_s001,S,,1,0
1001_t0019_s001,S; CH,ATTR; REB; SE,2,3
1001_t0020_s001,S; TG,,2,0
1001_t0021_s001,YNQ; Q-RHET,,2,0
1001_t0021_s002,S; CH,PER; AEX; REB,2,3
1001_t0022_s001,IAFA-OF; TT,PER,2,1
1001_t0022_s002,S,,1,0
1001_t0022_s003,S,IP,1,1
1001_t0022_s004,S-Inform; HS,SE,2,1
1001_t0022_s005,S; S-Inform,ATTR; SE,2,2
1001_t0022_s006,S,CB,1,1
1001_t0022_s007,S,CB; SE,1,2
1001_t0022_s008,S,IP; REB,1,2
1001_t0022_s009,S; S-Inform,ATTR; SE,2,2
1001_t0022_s010,S,REB,1,1
1001_t0022_s011,S; MS,IT; IP,2,2
1001_t0022_s012,S,IT; IP; SE,1,3
1001_t0023_s001,S,,1,0
1001_t0023_s002,TG,,1,0
1001_t0024_s001,TT,,1,0
1001_t0024_s002,S; CH,REB; SE,2,2
1001_t0024_s003,S; CH,REB; SE,2,2
1001_t0024_s004,YNQ,BQ; CB,1,2
1001_t0025_s001,S; ANS,IP,2,1
1001_t0025_s002,S,PB; IP; ATTR,1,3
1001_t0025_s003,S,PB; ATTR,1,2
1001_t0025_s004,S; IAFA-OF,IP,2,1
1001_t0025_s005,S-Inform,,1,0
1001_t0025_s006,S,IP,1,1
1001_t0025_s007,S-Inform; INT,IT; SE,2,2
1001_t0025_s008,S; EXPL,CB,2,1
1001_t0025_s009,S; EXPL,IP,2,1
1001_t0025_s010,S,IP,1,1
1001_t0025_s011,S,,1,0
1001_t0025_s012,S-Inform; HS,IT; SE,2,2
1001_t0025_s013,S-Inform; HS,,2,0
1001_t0025_s014,S-Inform,SE,1,1
1001_t0025_s015,S; EXPL,IP; CB,2,2
1001_t0025_s016,S,IT; SE,1,2
1001_t0025_s017,S,AE; IP,1,2
1001_t0025_s018,IAFA; HS,CB,2,1
1001_t0025_s019,S-Inform,CB; SE,1,2
1001_t0026_s001,TG,,1,0
1001_t0027_s001,S; IAFA,AE; REB,2,2
1001_t0027_s002,S-Inform; CH,AF; ATTR; REB; SE,2,4
1001_t0027_s003,S-Inform,AE; SE,1,2
1001_t0027_s004,S,AE; REB,1,2
1001_t0027_s005,S-Inform; HS,ATTR; SE,2,2
1001_t0027_s006,S,IT; IP,1,2
1001_t0028_s001,S; TG,,2,0
1001_t0028_s002,S-Inform,,1,0
1001_t0029_s001,S,,1,0
1001_t0029_s002,S; HS,,2,0
1001_t0029_s003,S-Inform,AE,1,1
1001_t0029_s004,Q-W; OQ,,2,0
1001_t0030_s001,S,AF; DF,1,2
1001_t0030_s002,S,IP,1,1
1001_t0030_s003,S-Inform,IT; SE,1,2
1001_t0030_s004,S,IP,1,1
1001_t0030_s005,S; ANS,IP,2,1
1001_t0030_s006,S,AF; AP; IT,1,3
1001_t0030_s007,S,IT,1,1
1001_t0030_s008,S,AF; UF,1,2
1001_t0030_s009,S; EXPL,IP,2,1
1001_t0030_s010,S,AF; IP; CB,1,3
1001_t0030_s011,S,AF; IP; CB,1,3
1001_t0030_s012,S; S-Inform,REB; SE,2,2
1001_t0030_s013,S,CB,1,1
1001_t0030_s014,S; EXPL,AF; CB,2,2
1001_t0030_s015,S,IP,1,1
1001_t0030_s016,S,IP,1,1
1001_t0030_s017,S,IP,1,1
1001_t0030_s018,S,,1,0
1001_t0030_s019,S,AF; IP,1,2
1001_t0031_s001,TG; T-REQ,,2,0
1001_t0032_s001,S; CH,REB,2,1
1001_t0033_s001,S; DIS,REB,2,1
1001_t0034_s001,S-Inform; CH,AE; REB,2,2
1001_t0034_s002,S; HS,AE,2,1
1001_t0034_s003,S,AE,1,1
1001_t0034_s004,S,AE,1,1
1001_t0034_s005,S,AE,1,1
1001_t0034_s006,S; INT,,2,0
1001_t0034_s007,S; S-Inform,,2,0
1001_t0034_s008,S,IP,1,1
1001_t0034_s009,S,UF,1,1
1001_t0035_s001,TG,,1,0
1001_t0036_s001,ANS,,1,0
1001_t0036_s002,S; MS,AF,2,1
1001_t0036_s003,S-Inform,AF,1,1
1001_t0036_s004,OQ; SEEP,,2,0
1001_t0037_s001,S; TT,DF; REB,2,2
1001_t0037_s002,S,,1,0
1001_t0037_s003,S; INT,IT; IP,2,2
1001_t0037_s004,S; CH,ATTR; REB,2,2
1001_t0037_s005,Q-RHET; HS,REB; CB,2,2
1001_t0037_s006,S-Inform; HS,REB,2,1
1001_t0037_s007,S; CH,ATTR; REB,2,2
1001_t0038_s001,IAFA; TT,,2,0
1001_t0038_s002,S,,1,0
1001_t0038_s003,IAFA; TG,,2,0
1001_t0039_s001,TT,,1,0
1001_t0039_s002,S; S-Inform; IAFA,AF; IP,3,2
1001_t0039_s003,S; IAFA,IP,2,1
1001_t0039_s004,S,IP,1,1
1001_t0039_s005,S; CH,ATTR; REB,2,2
1001_t0039_s006,S; AGR,IP,2,1
1001_t0039_s007,S,,1,0
1001_t0039_s008,S,IT; IP,1,2
1001_t0040_s001,S,,1,0
1001_t0040_s002,S,,1,0
1001_t0041_s001,S; IAFA,IP,2,1
1001_t0041_s002,S,,1,0
1001_t0041_s003,S,,1,0
1001_t0041_s004,S; CH,REB,2,1
1001_t0041_s005,S,,1,0
1001_t0041_s006,S,,1,0
1001_t0041_s007,S,AE,1,1
1001_t0041_s008,S; S-Inform,IT,2,1
1001_t0041_s009,S; IAFA,AF; IP,2,2
1001_t0041_s010,S,AF,1,1
1001_t0041_s011,S,,1,0
1001_t0042_s001,S,,1,0
1001_t0042_s002,S,,1,0
1001_t0043_s001,GR,,1,0
1001_t0043_s002,GR,,1,0
1001_t0043_s003,S; MS,,2,0
1001_t0043_s004,S,PER,1,1
1001_t0044_s001,Q-W; INT,,2,0
1001_t0045_s001,S,PER,1,1
1001_t0045_s002,S; CH,PER; REB,2,2
1001_t0045_s003,S; CH; HS,ATTR; REB; SE,3,3
1001_t0045_s004,S,,1,0
1001_t0045_s005,OQ; S,,2,0
1001_t0045_s006,OQ; IAFA,CB,2,1
